Workbook

Sheet Read_Me
A1: FY25 CFC order scenario tool
A3: How to use
A4: 1. Change the yellow cells on the Inputs sheet (blue text = editable inputs).
A5: 2. The Daily sheet recalculates every scenario for each day of FY25.
A6: 3. The Summary sheet shows annual and monthly results and the change versus the base case.
A8: Scenario formula (per day)
A9: Orders = Baseline x (1 + market shift if date >= shift start) x (1 + promo uplift x promo flag)
A10: Promo flag = 1 on calendar promotion days, or on extra monthly promotion days when that scenario includes them.
A12: Sources
A13: Baseline and prediction error come from src/forecast.py (outputs/forecast_daily.csv).
A14: Promotion dates and uplift percentages are planning assumptions: FY24 data shows no measurable promotional uplift.

Sheet Summary
A1: Metric | B1: Base case | C1: Scenario 1: Increased promotions | D1: Scenario 2: Market downturn
A2: Total FY25 orders | B2: =SUM(Daily!G2:G366) -> 148586.2 | C2: =SUM(Daily!H2:H366) -> 155125.2 | D2: =SUM(Daily!I2:I366) -> 141232.34
A3: Change vs base case (orders) | B3: =B2-$B$2 -> 0 | C3: =C2-$B$2 -> 6539 | D3: =D2-$B$2 -> -7353.86
A4: Change vs base case (%) | B4: =B2/$B$2-1 -> 0 | C4: =C2/$B$2-1 -> 0.044008125 | D4: =D2/$B$2-1 -> -0.049492214
A5: Average orders per day | B5: =AVERAGE(Daily!G2:G366) -> 407.08548 | C5: =AVERAGE(Daily!H2:H366) -> 425.00055 | D5: =AVERAGE(Daily!I2:I366) -> 386.93792
A6: Peak day (expected) | B6: =MAX(Daily!G2:G366) -> 503 | C6: =MAX(Daily!H2:H366) -> 603.6 | D6: =MAX(Daily!I2:I366) -> 503
A7: Peak day (80% upper bound) | B7: =B6*(1+Inputs!$B$10*Inputs!$B$9/Inputs!$B$8) -> 592.712 | C7: =C6*(1+Inputs!$B$10*Inputs!$B$9/Inputs!$B$8) -> 711.2544 | D7: =D6*(1+Inputs!$B$10*Inputs!$B$9/Inputs!$B$8) -> 592.712
A8: Days where 80% upper bound exceeds planning capacity | B8: =COUNTIF(Daily!G2:G366,">"&(Inputs!$B$11/(1+Inputs!$B$10*Inputs!$B$9/Inputs!$B$8))) -> 17 | C8: =COUNTIF(Daily!H2:H366,">"&(Inputs!$B$11/(1+Inputs!$B$10*Inputs!$B$9/Inputs!$B$8))) -> 41 | D8: =COUNTIF(Daily!I2:I366,">"&(Inputs!$B$11/(1+Inputs!$B$10*Inputs!$B$9/Inputs!$B$8))) -> 10
A10: Monthly orders
A11: Month | B11: Base case | C11: Scenario 1: Increased promotions | D11: Scenario 2: Market downturn
A12: 2024-07 | B12: =SUMIFS(Daily!G$2:G$366,Daily!$B$2:$B$366,$A12) -> 12675.6 | C12: =SUMIFS(Daily!H$2:H$366,Daily!$B$2:$B$366,$A12) -> 13279.2 | D12: =SUMIFS(Daily!I$2:I$366,Daily!$B$2:$B$366,$A12) -> 12675.6
A13: 2024-08 | B13: =SUMIFS(Daily!G$2:G$366,Daily!$B$2:$B$366,$A13) -> 12474.4 | C13: =SUMIFS(Daily!H$2:H$366,Daily!$B$2:$B$366,$A13) -> 12876.8 | D13: =SUMIFS(Daily!I$2:I$366,Daily!$B$2:$B$366,$A13) -> 12474.4
A14: 2024-09 | B14: =SUMIFS(Daily!G$2:G$366,Daily!$B$2:$B$366,$A14) -> 12072 | C14: =SUMIFS(Daily!H$2:H$366,Daily!$B$2:$B$366,$A14) -> 12474.4 | D14: =SUMIFS(Daily!I$2:I$366,Daily!$B$2:$B$366,$A14) -> 12072
A15: 2024-10 | B15: =SUMIFS(Daily!G$2:G$366,Daily!$B$2:$B$366,$A15) -> 12474.4 | C15: =SUMIFS(Daily!H$2:H$366,Daily!$B$2:$B$366,$A15) -> 12876.8 | D15: =SUMIFS(Daily!I$2:I$366,Daily!$B$2:$B$366,$A15) -> 12474.4
A16: 2024-11 | B16: =SUMIFS(Daily!G$2:G$366,Daily!$B$2:$B$366,$A16) -> 12474.4 | C16: =SUMIFS(Daily!H$2:H$366,Daily!$B$2:$B$366,$A16) -> 13279.2 | D16: =SUMIFS(Daily!I$2:I$366,Daily!$B$2:$B$366,$A16) -> 12474.4
A17: 2024-12 | B17: =SUMIFS(Daily!G$2:G$366,Daily!$B$2:$B$366,$A17) -> 12876.8 | C17: =SUMIFS(Daily!H$2:H$366,Daily!$B$2:$B$366,$A17) -> 13681.6 | D17: =SUMIFS(Daily!I$2:I$366,Daily!$B$2:$B$366,$A17) -> 12876.8
A18: 2025-01 | B18: =SUMIFS(Daily!G$2:G$366,Daily!$B$2:$B$366,$A18) -> 12474.4 | C18: =SUMIFS(Daily!H$2:H$366,Daily!$B$2:$B$366,$A18) -> 12876.8 | D18: =SUMIFS(Daily!I$2:I$366,Daily!$B$2:$B$366,$A18) -> 11226.96
A19: 2025-02 | B19: =SUMIFS(Daily!G$2:G$366,Daily!$B$2:$B$366,$A19) -> 11267.2 | C19: =SUMIFS(Daily!H$2:H$366,Daily!$B$2:$B$366,$A19) -> 11669.6 | D19: =SUMIFS(Daily!I$2:I$366,Daily!$B$2:$B$366,$A19) -> 10140.48
A20: 2025-03 | B20: =SUMIFS(Daily!G$2:G$366,Daily!$B$2:$B$366,$A20) -> 12474.4 | C20: =SUMIFS(Daily!H$2:H$366,Daily!$B$2:$B$366,$A20) -> 12876.8 | D20: =SUMIFS(Daily!I$2:I$366,Daily!$B$2:$B$366,$A20) -> 11226.96
A21: 2025-04 | B21: =SUMIFS(Daily!G$2:G$366,Daily!$B$2:$B$366,$A21) -> 12072 | C21: =SUMIFS(Daily!H$2:H$366,Daily!$B$2:$B$366,$A21) -> 12474.4 | D21: =SUMIFS(Daily!I$2:I$366,Daily!$B$2:$B$366,$A21) -> 10864.8
A22: 2025-05 | B22: =SUMIFS(Daily!G$2:G$366,Daily!$B$2:$B$366,$A22) -> 12474.4 | C22: =SUMIFS(Daily!H$2:H$366,Daily!$B$2:$B$366,$A22) -> 12876.8 | D22: =SUMIFS(Daily!I$2:I$366,Daily!$B$2:$B$366,$A22) -> 11226.96
A23: 2025-06 | B23: =SUMIFS(Daily!G$2:G$366,Daily!$B$2:$B$366,$A23) -> 12776.2 | C23: =SUMIFS(Daily!H$2:H$366,Daily!$B$2:$B$366,$A23) -> 13882.8 | D23: =SUMIFS(Daily!I$2:I$366,Daily!$B$2:$B$366,$A23) -> 11498.58

Sheet Inputs
A1: Parameter | B1: Base case | C1: Scenario 1: Increased promotions | D1: Scenario 2: Market downturn | E1: Notes
A2: Promotional uplift (%) | B2: 0.25 | C2: 0.5 | D2: 0.25 | E2: Applied to promotion days. Assumption: no uplift is visible in FY24 data.
A3: Include extra monthly promotions (1 = yes, 0 = no) | B3: 0 | C3: 1 | D3: 0 | E3: Adds the first Friday and Saturday of each month as promotion days.
A4: Market shift in underlying demand (%) | B4: 0 | C4: 0 | D4: -0.1 | E4: Applied to the baseline from the shift start date onwards.
A5: Market shift start date | B5: 45658 | C5: 45658 | D5: 45658
A7: Model constants (from src/forecast.py)
A8: Baseline orders per day | B8: 402.4 | E8: Holt-Winters level for FY25.
A9: Daily prediction error (orders, out-of-sample RMSE) | B9: 56 | E9: Rolling-origin backtest, 6 x 30 days.
A10: z-value for 80% interval | B10: 1.2816
A11: Planning capacity (orders per day) | B11: 550 | E11: Illustrative. Replace with actual CFC capacity.

Sheet Daily
A1: Date | B1: Month | C1: Baseline | D1: Promotion | E1: Calendar promo (1/0) | F1: Extra monthly promo candidate (1/0) | G1: Base case | H1: Scenario 1: Increased promotions | I1: Scenario 2: Market downturn
A2: 45474 | B2: =TEXT(A2,"yyyy-mm") -> 2024-07 | C2: 402.4 | E2: 0 | F2: 0 | G2: =C2*(1+IF(A2>=Inputs!$B$5,Inputs!$B$4,0))*(1+Inputs!$B$2*MAX(E2,F2*Inputs!$B$3)) -> 402.4 | H2: =C2*(1+IF(A2>=Inputs!$C$5,Inputs!$C$4,0))*(1+Inputs!$C$2*MAX(E2,F2*Inputs!$C$3)) -> 402.4 | I2: =C2*(1+IF(A2>=Inputs!$D$5,Inputs!$D$4,0))*(1+Inputs!$D$2*MAX(E2,F2*Inputs!$D$3)) -> 402.4
A3: 45475 | B3: =TEXT(A3,"yyyy-mm") -> 2024-07 | C3: 402.4 | E3: 0 | F3: 0 | G3: =C3*(1+IF(A3>=Inputs!$B$5,Inputs!$B$4,0))*(1+Inputs!$B$2*MAX(E3,F3*Inputs!$B$3)) -> 402.4 | H3: =C3*(1+IF(A3>=Inputs!$C$5,Inputs!$C$4,0))*(1+Inputs!$C$2*MAX(E3,F3*Inputs!$C$3)) -> 402.4 | I3: =C3*(1+IF(A3>=Inputs!$D$5,Inputs!$D$4,0))*(1+Inputs!$D$2*MAX(E3,F3*Inputs!$D$3)) -> 402.4
A4: 45476 | B4: =TEXT(A4,"yyyy-mm") -> 2024-07 | C4: 402.4 | E4: 0 | F4: 0 | G4: =C4*(1+IF(A4>=Inputs!$B$5,Inputs!$B$4,0))*(1+Inputs!$B$2*MAX(E4,F4*Inputs!$B$3)) -> 402.4 | H4: =C4*(1+IF(A4>=Inputs!$C$5,Inputs!$C$4,0))*(1+Inputs!$C$2*MAX(E4,F4*Inputs!$C$3)) -> 402.4 | I4: =C4*(1+IF(A4>=Inputs!$D$5,Inputs!$D$4,0))*(1+Inputs!$D$2*MAX(E4,F4*Inputs!$D$3)) -> 402.4
A5: 45477 | B5: =TEXT(A5,"yyyy-mm") -> 2024-07 | C5: 402.4 | E5: 0 | F5: 0 | G5: =C5*(1+IF(A5>=Inputs!$B$5,Inputs!$B$4,0))*(1+Inputs!$B$2*MAX(E5,F5*Inputs!$B$3)) -> 402.4 | H5: =C5*(1+IF(A5>=Inputs!$C$5,Inputs!$C$4,0))*(1+Inputs!$C$2*MAX(E5,F5*Inputs!$C$3)) -> 402.4 | I5: =C5*(1+IF(A5>=Inputs!$D$5,Inputs!$D$4,0))*(1+Inputs!$D$2*MAX(E5,F5*Inputs!$D$3)) -> 402.4
A6: 45478 | B6: =TEXT(A6,"yyyy-mm") -> 2024-07 | C6: 402.4 | E6: 0 | F6: 1 | G6: =C6*(1+IF(A6>=Inputs!$B$5,Inputs!$B$4,0))*(1+Inputs!$B$2*MAX(E6,F6*Inputs!$B$3)) -> 402.4 | H6: =C6*(1+IF(A6>=Inputs!$C$5,Inputs!$C$4,0))*(1+Inputs!$C$2*MAX(E6,F6*Inputs!$C$3)) -> 603.6 | I6: =C6*(1+IF(A6>=Inputs!$D$5,Inputs!$D$4,0))*(1+Inputs!$D$2*MAX(E6,F6*Inputs!$D$3)) -> 402.4
A7: 45479 | B7: =TEXT(A7,"yyyy-mm") -> 2024-07 | C7: 402.4 | E7: 0 | F7: 1 | G7: =C7*(1+IF(A7>=Inputs!$B$5,Inputs!$B$4,0))*(1+Inputs!$B$2*MAX(E7,F7*Inputs!$B$3)) -> 402.4 | H7: =C7*(1+IF(A7>=Inputs!$C$5,Inputs!$C$4,0))*(1+Inputs!$C$2*MAX(E7,F7*Inputs!$C$3)) -> 603.6 | I7: =C7*(1+IF(A7>=Inputs!$D$5,Inputs!$D$4,0))*(1+Inputs!$D$2*MAX(E7,F7*Inputs!$D$3)) -> 402.4
A8: 45480 | B8: =TEXT(A8,"yyyy-mm") -> 2024-07 | C8: 402.4 | E8: 0 | F8: 0 | G8: =C8*(1+IF(A8>=Inputs!$B$5,Inputs!$B$4,0))*(1+Inputs!$B$2*MAX(E8,F8*Inputs!$B$3)) -> 402.4 | H8: =C8*(1+IF(A8>=Inputs!$C$5,Inputs!$C$4,0))*(1+Inputs!$C$2*MAX(E8,F8*Inputs!$C$3)) -> 402.4 | I8: =C8*(1+IF(A8>=Inputs!$D$5,Inputs!$D$4,0))*(1+Inputs!$D$2*MAX(E8,F8*Inputs!$D$3)) -> 402.4
A9: 45481 | B9: =TEXT(A9,"yyyy-mm") -> 2024-07 | C9: 402.4 | E9: 0 | F9: 0 | G9: =C9*(1+IF(A9>=Inputs!$B$5,Inputs!$B$4,0))*(1+Inputs!$B$2*MAX(E9,F9*Inputs!$B$3)) -> 402.4 | H9: =C9*(1+IF(A9>=Inputs!$C$5,Inputs!$C$4,0))*(1+Inputs!$C$2*MAX(E9,F9*Inputs!$C$3)) -> 402.4 | I9: =C9*(1+IF(A9>=Inputs!$D$5,Inputs!$D$4,0))*(1+Inputs!$D$2*MAX(E9,F9*Inputs!$D$3)) -> 402.4
A10: 45482 | B10: =TEXT(A10,"yyyy-mm") -> 2024-07 | C10: 402.4 | E10: 0 | F10: 0 | G10: =C10*(1+IF(A10>=Inputs!$B$5,Inputs!$B$4,0))*(1+Inputs!$B$2*MAX(E10,F10*Inputs!$B$3)) -> 402.4 | H10: =C10*(1+IF(A10>=Inputs!$C$5,Inputs!$C$4,0))*(1+Inputs!$C$2*MAX(E10,F10*Inputs!$C$3)) -> 402.4 | I10: =C10*(1+IF(A10>=Inputs!$D$5,Inputs!$D$4,0))*(1+Inputs!$D$2*MAX(E10,F10*Inputs!$D$3)) -> 402.4
A11: 45483 | B11: =TEXT(A11,"yyyy-mm") -> 2024-07 | C11: 402.4 | E11: 0 | F11: 0 | G11: =C11*(1+IF(A11>=Inputs!$B$5,Inputs!$B$4,0))*(1+Inputs!$B$2*MAX(E11,F11*Inputs!$B$3)) -> 402.4 | H11: =C11*(1+IF(A11>=Inputs!$C$5,Inputs!$C$4,0))*(1+Inputs!$C$2*MAX(E11,F11*Inputs!$C$3)) -> 402.4 | I11: =C11*(1+IF(A11>=Inputs!$D$5,Inputs!$D$4,0))*(1+Inputs!$D$2*MAX(E11,F11*Inputs!$D$3)) -> 402.4
A12: 45484 | B12: =TEXT(A12,"yyyy-mm") -> 2024-07 | C12: 402.4 | E12: 0 | F12: 0 | G12: =C12*(1+IF(A12>=Inputs!$B$5,Inputs!$B$4,0))*(1+Inputs!$B$2*MAX(E12,F12*Inputs!$B$3)) -> 402.4 | H12: =C12*(1+IF(A12>=Inputs!$C$5,Inputs!$C$4,0))*(1+Inputs!$C$2*MAX(E12,F12*Inputs!$C$3)) -> 402.4 | I12: =C12*(1+IF(A12>=Inputs!$D$5,Inputs!$D$4,0))*(1+Inputs!$D$2*MAX(E12,F12*Inputs!$D$3)) -> 402.4
A13: 45485 | B13: =TEXT(A13,"yyyy-mm") -> 2024-07 | C13: 402.4 | E13: 0 | F13: 0 | G13: =C13*(1+IF(A13>=Inputs!$B$5,Inputs!$B$4,0))*(1+Inputs!$B$2*MAX(E13,F13*Inputs!$B$3)) -> 402.4 | H13: =C13*(1+IF(A13>=Inputs!$C$5,Inputs!$C$4,0))*(1+Inputs!$C$2*MAX(E13,F13*Inputs!$C$3)) -> 402.4 | I13: =C13*(1+IF(A13>=Inputs!$D$5,Inputs!$D$4,0))*(1+Inputs!$D$2*MAX(E13,F13*Inputs!$D$3)) -> 402.4
... A16: 45488 | B16: =TEXT(A16,"yyyy-mm") -> 2024-07 | C16: 402.4 | E16: 0 | F16: 0 | G16: =C16*(1+IF(A16>=Inputs!$B$5,Inputs!$B$4,0))*(1+Inputs!$B$2*MAX(E16,F16*Inputs!$B$3)) -> 402.4 | H16: =C16*(1+IF(A16>=Inputs!$C$5,Inputs!$C$4,0))*(1+Inputs!$C$2*MAX(E16,F16*Inputs!$C$3)) -> 402.4 | I16: =C16*(1+IF(A16>=Inputs!$D$5,Inputs!$D$4,0))*(1+Inputs!$D$2*MAX(E16,F16*Inputs!$D$3)) -> 402.4
A17: 45489 | B17: =TEXT(A17,"yyyy-mm") -> 2024-07 | C17: 402.4 | D17: Competitor mega sale (July) | E17: 1 | F17: 0 | G17: =C17*(1+IF(A17>=Inputs!$B$5,Inputs!$B$4,0))*(1+Inputs!$B$2*MAX(E17,F17*Inputs!$B$3)) -> 503 | H17: =C17*(1+IF(A17>=Inputs!$C$5,Inputs!$C$4,0))*(1+Inputs!$C$2*MAX(E17,F17*Inputs!$C$3)) -> 603.6 | I17: =C17*(1+IF(A17>=Inputs!$D$5,Inputs!$D$4,0))*(1+Inputs!$D$2*MAX(E17,F17*Inputs!$D$3)) -> 503
A18: 45490 | B18: =TEXT(A18,"yyyy-mm") -> 2024-07 | C18: 402.4 | D18: Competitor mega sale (July) | E18: 1 | F18: 0 | G18: =C18*(1+IF(A18>=Inputs!$B$5,Inputs!$B$4,0))*(1+Inputs!$B$2*MAX(E18,F18*Inputs!$B$3)) -> 503 | H18: =C18*(1+IF(A18>=Inputs!$C$5,Inputs!$C$4,0))*(1+Inputs!$C$2*MAX(E18,F18*Inputs!$C$3)) -> 603.6 | I18: =C18*(1+IF(A18>=Inputs!$D$5,Inputs!$D$4,0))*(1+Inputs!$D$2*MAX(E18,F18*Inputs!$D$3)) -> 503
A19: 45491 | B19: =TEXT(A19,"yyyy-mm") -> 2024-07 | C19: 402.4 | E19: 0 | F19: 0 | G19: =C19*(1+IF(A19>=Inputs!$B$5,Inputs!$B$4,0))*(1+Inputs!$B$2*MAX(E19,F19*Inputs!$B$3)) -> 402.4 | H19: =C19*(1+IF(A19>=Inputs!$C$5,Inputs!$C$4,0))*(1+Inputs!$C$2*MAX(E19,F19*Inputs!$C$3)) -> 402.4 | I19: =C19*(1+IF(A19>=Inputs!$D$5,Inputs!$D$4,0))*(1+Inputs!$D$2*MAX(E19,F19*Inputs!$D$3)) -> 402.4
A20: 45492 | B20: =TEXT(A20,"yyyy-mm") -> 2024-07 | C20: 402.4 | E20: 0 | F20: 0 | G20: =C20*(1+IF(A20>=Inputs!$B$5,Inputs!$B$4,0))*(1+Inputs!$B$2*MAX(E20,F20*Inputs!$B$3)) -> 402.4 | H20: =C20*(1+IF(A20>=Inputs!$C$5,Inputs!$C$4,0))*(1+Inputs!$C$2*MAX(E20,F20*Inputs!$C$3)) -> 402.4 | I20: =C20*(1+IF(A20>=Inputs!$D$5,Inputs!$D$4,0))*(1+Inputs!$D$2*MAX(E20,F20*Inputs!$D$3)) -> 402.4
A21: 45493 | B21: =TEXT(A21,"yyyy-mm") -> 2024-07 | C21: 402.4 | E21: 0 | F21: 0 | G21: =C21*(1+IF(A21>=Inputs!$B$5,Inputs!$B$4,0))*(1+Inputs!$B$2*MAX(E21,F21*Inputs!$B$3)) -> 402.4 | H21: =C21*(1+IF(A21>=Inputs!$C$5,Inputs!$C$4,0))*(1+Inputs!$C$2*MAX(E21,F21*Inputs!$C$3)) -> 402.4 | I21: =C21*(1+IF(A21>=Inputs!$D$5,Inputs!$D$4,0))*(1+Inputs!$D$2*MAX(E21,F21*Inputs!$D$3)) -> 402.4
A22: 45494 | B22: =TEXT(A22,"yyyy-mm") -> 2024-07 | C22: 402.4 | E22: 0 | F22: 0 | G22: =C22*(1+IF(A22>=Inputs!$B$5,Inputs!$B$4,0))*(1+Inputs!$B$2*MAX(E22,F22*Inputs!$B$3)) -> 402.4 | H22: =C22*(1+IF(A22>=Inputs!$C$5,Inputs!$C$4,0))*(1+Inputs!$C$2*MAX(E22,F22*Inputs!$C$3)) -> 402.4 | I22: =C22*(1+IF(A22>=Inputs!$D$5,Inputs!$D$4,0))*(1+Inputs!$D$2*MAX(E22,F22*Inputs!$D$3)) -> 402.4
A23: 45495 | B23: =TEXT(A23,"yyyy-mm") -> 2024-07 | C23: 402.4 | E23: 0 | F23: 0 | G23: =C23*(1+IF(A23>=Inputs!$B$5,Inputs!$B$4,0))*(1+Inputs!$B$2*MAX(E23,F23*Inputs!$B$3)) -> 402.4 | H23: =C23*(1+IF(A23>=Inputs!$C$5,Inputs!$C$4,0))*(1+Inputs!$C$2*MAX(E23,F23*Inputs!$C$3)) -> 402.4 | I23: =C23*(1+IF(A23>=Inputs!$D$5,Inputs!$D$4,0))*(1+Inputs!$D$2*MAX(E23,F23*Inputs!$D$3)) -> 402.4
A24: 45496 | B24: =TEXT(A24,"yyyy-mm") -> 2024-07 | C24: 402.4 | E24: 0 | F24: 0 | G24: =C24*(1+IF(A24>=Inputs!$B$5,Inputs!$B$4,0))*(1+Inputs!$B$2*MAX(E24,F24*Inputs!$B$3)) -> 402.4 | H24: =C24*(1+IF(A24>=Inputs!$C$5,Inputs!$C$4,0))*(1+Inputs!$C$2*MAX(E24,F24*Inputs!$C$3)) -> 402.4 | I24: =C24*(1+IF(A24>=Inputs!$D$5,Inputs!$D$4,0))*(1+Inputs!$D$2*MAX(E24,F24*Inputs!$D$3)) -> 402.4
A25: 45497 | B25: =TEXT(A25,"yyyy-mm") -> 2024-07 | C25: 402.4 | E25: 0 | F25: 0 | G25: =C25*(1+IF(A25>=Inputs!$B$5,Inputs!$B$4,0))*(1+Inputs!$B$2*MAX(E25,F25*Inputs!$B$3)) -> 402.4 | H25: =C25*(1+IF(A25>=Inputs!$C$5,Inputs!$C$4,0))*(1+Inputs!$C$2*MAX(E25,F25*Inputs!$C$3)) -> 402.4 | I25: =C25*(1+IF(A25>=Inputs!$D$5,Inputs!$D$4,0))*(1+Inputs!$D$2*MAX(E25,F25*Inputs!$D$3)) -> 402.4
A26: 45498 | B26: =TEXT(A26,"yyyy-mm") -> 2024-07 | C26: 402.4 | E26: 0 | F26: 0 | G26: =C26*(1+IF(A26>=Inputs!$B$5,Inputs!$B$4,0))*(1+Inputs!$B$2*MAX(E26,F26*Inputs!$B$3)) -> 402.4 | H26: =C26*(1+IF(A26>=Inputs!$C$5,Inputs!$C$4,0))*(1+Inputs!$C$2*MAX(E26,F26*Inputs!$C$3)) -> 402.4 | I26: =C26*(1+IF(A26>=Inputs!$D$5,Inputs!$D$4,0))*(1+Inputs!$D$2*MAX(E26,F26*Inputs!$D$3)) -> 402.4
A27: 45499 | B27: =TEXT(A27,"yyyy-mm") -> 2024-07 | C27: 402.4 | E27: 0 | F27: 0 | G27: =C27*(1+IF(A27>=Inputs!$B$5,Inputs!$B$4,0))*(1+Inputs!$B$2*MAX(E27,F27*Inputs!$B$3)) -> 402.4 | H27: =C27*(1+IF(A27>=Inputs!$C$5,Inputs!$C$4,0))*(1+Inputs!$C$2*MAX(E27,F27*Inputs!$C$3)) -> 402.4 | I27: =C27*(1+IF(A27>=Inputs!$D$5,Inputs!$D$4,0))*(1+Inputs!$D$2*MAX(E27,F27*Inputs!$D$3)) -> 402.4
A28: 45500 | B28: =TEXT(A28,"yyyy-mm") -> 2024-07 | C28: 402.4 | E28: 0 | F28: 0 | G28: =C28*(1+IF(A28>=Inputs!$B$5,Inputs!$B$4,0))*(1+Inputs!$B$2*MAX(E28,F28*Inputs!$B$3)) -> 402.4 | H28: =C28*(1+IF(A28>=Inputs!$C$5,Inputs!$C$4,0))*(1+Inputs!$C$2*MAX(E28,F28*Inputs!$C$3)) -> 402.4 | I28: =C28*(1+IF(A28>=Inputs!$D$5,Inputs!$D$4,0))*(1+Inputs!$D$2*MAX(E28,F28*Inputs!$D$3)) -> 402.4
A29: 45501 | B29: =TEXT(A29,"yyyy-mm") -> 2024-07 | C29: 402.4 | E29: 0 | F29: 0 | G29: =C29*(1+IF(A29>=Inputs!$B$5,Inputs!$B$4,0))*(1+Inputs!$B$2*MAX(E29,F29*Inputs!$B$3)) -> 402.4 | H29: =C29*(1+IF(A29>=Inputs!$C$5,Inputs!$C$4,0))*(1+Inputs!$C$2*MAX(E29,F29*Inputs!$C$3)) -> 402.4 | I29: =C29*(1+IF(A29>=Inputs!$D$5,Inputs!$D$4,0))*(1+Inputs!$D$2*MAX(E29,F29*Inputs!$D$3)) -> 402.4
A30: 45502 | B30: =TEXT(A30,"yyyy-mm") -> 2024-07 | C30: 402.4 | E30: 0 | F30: 0 | G30: =C30*(1+IF(A30>=Inputs!$B$5,Inputs!$B$4,0))*(1+Inputs!$B$2*MAX(E30,F30*Inputs!$B$3)) -> 402.4 | H30: =C30*(1+IF(A30>=Inputs!$C$5,Inputs!$C$4,0))*(1+Inputs!$C$2*MAX(E30,F30*Inputs!$C$3)) -> 402.4 | I30: =C30*(1+IF(A30>=Inputs!$D$5,Inputs!$D$4,0))*(1+Inputs!$D$2*MAX(E30,F30*Inputs!$D$3)) -> 402.4
... A135: 45607 | B135: =TEXT(A135,"yyyy-mm") -> 2024-11 | C135: 402.4 | E135: 0 | F135: 0 | G135: =C135*(1+IF(A135>=Inputs!$B$5,Inputs!$B$4,0))*(1+Inputs!$B$2*MAX(E135,F135*Inputs!$B$3)) -> 402.4 | H135: =C135*(1+IF(A135>=Inputs!$C$5,Inputs!$C$4,0))*(1+Inputs!$C$2*MAX(E135,F135*Inputs!$C$3)) -> 402.4 | I135: =C135*(1+IF(A135>=Inputs!$D$5,Inputs!$D$4,0))*(1+Inputs!$D$2*MAX(E135,F135*Inputs!$D$3)) -> 402.4
A136: 45608 | B136: =TEXT(A136,"yyyy-mm") -> 2024-11 | C136: 402.4 | D136: Competitor mega sale (November) | E136: 1 | F136: 0 | G136: =C136*(1+IF(A136>=Inputs!$B$5,Inputs!$B$4,0))*(1+Inputs!$B$2*MAX(E136,F136*Inputs!$B$3)) -> 503 | H136: =C136*(1+IF(A136>=Inputs!$C$5,Inputs!$C$4,0))*(1+Inputs!$C$2*MAX(E136,F136*Inputs!$C$3)) -> 603.6 | I136: =C136*(1+IF(A136>=Inputs!$D$5,Inputs!$D$4,0))*(1+Inputs!$D$2*MAX(E136,F136*Inputs!$D$3)) -> 503
A137: 45609 | B137: =TEXT(A137,"yyyy-mm") -> 2024-11 | C137: 402.4 | D137: Competitor mega sale (November) | E137: 1 | F137: 0 | G137: =C137*(1+IF(A137>=Inputs!$B$5,Inputs!$B$4,0))*(1+Inputs!$B$2*MAX(E137,F137*Inputs!$B$3)) -> 503 | H137: =C137*(1+IF(A137>=Inputs!$C$5,Inputs!$C$4,0))*(1+Inputs!$C$2*MAX(E137,F137*Inputs!$C$3)) -> 603.6 | I137: =C137*(1+IF(A137>=Inputs!$D$5,Inputs!$D$4,0))*(1+Inputs!$D$2*MAX(E137,F137*Inputs!$D$3)) -> 503
A138: 45610 | B138: =TEXT(A138,"yyyy-mm") -> 2024-11 | C138: 402.4 | E138: 0 | F138: 0 | G138: =C138*(1+IF(A138>=Inputs!$B$5,Inputs!$B$4,0))*(1+Inputs!$B$2*MAX(E138,F138*Inputs!$B$3)) -> 402.4 | H138: =C138*(1+IF(A138>=Inputs!$C$5,Inputs!$C$4,0))*(1+Inputs!$C$2*MAX(E138,F138*Inputs!$C$3)) -> 402.4 | I138: =C138*(1+IF(A138>=Inputs!$D$5,Inputs!$D$4,0))*(1+Inputs!$D$2*MAX(E138,F138*Inputs!$D$3)) -> 402.4
A139: 45611 | B139: =TEXT(A139,"yyyy-mm") -> 2024-11 | C139: 402.4 | E139: 0 | F139: 0 | G139: =C139*(1+IF(A139>=Inputs!$B$5,Inputs!$B$4,0))*(1+Inputs!$B$2*MAX(E139,F139*Inputs!$B$3)) -> 402.4 | H139: =C139*(1+IF(A139>=Inputs!$C$5,Inputs!$C$4,0))*(1+Inputs!$C$2*MAX(E139,F139*Inputs!$C$3)) -> 402.4 | I139: =C139*(1+IF(A139>=Inputs!$D$5,Inputs!$D$4,0))*(1+Inputs!$D$2*MAX(E139,F139*Inputs!$D$3)) -> 402.4
A140: 45612 | B140: =TEXT(A140,"yyyy-mm") -> 2024-11 | C140: 402.4 | E140: 0 | F140: 0 | G140: =C140*(1+IF(A140>=Inputs!$B$5,Inputs!$B$4,0))*(1+Inputs!$B$2*MAX(E140,F140*Inputs!$B$3)) -> 402.4 | H140: =C140*(1+IF(A140>=Inputs!$C$5,Inputs!$C$4,0))*(1+Inputs!$C$2*MAX(E140,F140*Inputs!$C$3)) -> 402.4 | I140: =C140*(1+IF(A140>=Inputs!$D$5,Inputs!$D$4,0))*(1+Inputs!$D$2*MAX(E140,F140*Inputs!$D$3)) -> 402.4
A141: 45613 | B141: =TEXT(A141,"yyyy-mm") -> 2024-11 | C141: 402.4 | E141: 0 | F141: 0 | G141: =C141*(1+IF(A141>=Inputs!$B$5,Inputs!$B$4,0))*(1+Inputs!$B$2*MAX(E141,F141*Inputs!$B$3)) -> 402.4 | H141: =C141*(1+IF(A141>=Inputs!$C$5,Inputs!$C$4,0))*(1+Inputs!$C$2*MAX(E141,F141*Inputs!$C$3)) -> 402.4 | I141: =C141*(1+IF(A141>=Inputs!$D$5,Inputs!$D$4,0))*(1+Inputs!$D$2*MAX(E141,F141*Inputs!$D$3)) -> 402.4
A142: 45614 | B142: =TEXT(A142,"yyyy-mm") -> 2024-11 | C142: 402.4 | E142: 0 | F142: 0 | G142: =C142*(1+IF(A142>=Inputs!$B$5,Inputs!$B$4,0))*(1+Inputs!$B$2*MAX(E142,F142*Inputs!$B$3)) -> 402.4 | H142: =C142*(1+IF(A142>=Inputs!$C$5,Inputs!$C$4,0))*(1+Inputs!$C$2*MAX(E142,F142*Inputs!$C$3)) -> 402.4 | I142: =C142*(1+IF(A142>=Inputs!$D$5,Inputs!$D$4,0))*(1+Inputs!$D$2*MAX(E142,F142*Inputs!$D$3)) -> 402.4
A143: 45615 | B143: =TEXT(A143,"yyyy-mm") -> 2024-11 | C143: 402.4 | E143: 0 | F143: 0 | G143: =C143*(1+IF(A143>=Inputs!$B$5,Inputs!$B$4,0))*(1+Inputs!$B$2*MAX(E143,F143*Inputs!$B$3)) -> 402.4 | H143: =C143*(1+IF(A143>=Inputs!$C$5,Inputs!$C$4,0))*(1+Inputs!$C$2*MAX(E143,F143*Inputs!$C$3)) -> 402.4 | I143: =C143*(1+IF(A143>=Inputs!$D$5,Inputs!$D$4,0))*(1+Inputs!$D$2*MAX(E143,F143*Inputs!$D$3)) -> 402.4
A144: 45616 | B144: =TEXT(A144,"yyyy-mm") -> 2024-11 | C144: 402.4 | E144: 0 | F144: 0 | G144: =C144*(1+IF(A144>=Inputs!$B$5,Inputs!$B$4,0))*(1+Inputs!$B$2*MAX(E144,F144*Inputs!$B$3)) -> 402.4 | H144: =C144*(1+IF(A144>=Inputs!$C$5,Inputs!$C$4,0))*(1+Inputs!$C$2*MAX(E144,F144*Inputs!$C$3)) -> 402.4 | I144: =C144*(1+IF(A144>=Inputs!$D$5,Inputs!$D$4,0))*(1+Inputs!$D$2*MAX(E144,F144*Inputs!$D$3)) -> 402.4
A145: 45617 | B145: =TEXT(A145,"yyyy-mm") -> 2024-11 | C145: 402.4 | E145: 0 | F145: 0 | G145: =C145*(1+IF(A145>=Inputs!$B$5,Inputs!$B$4,0))*(1+Inputs!$B$2*MAX(E145,F145*Inputs!$B$3)) -> 402.4 | H145: =C145*(1+IF(A145>=Inputs!$C$5,Inputs!$C$4,0))*(1+Inputs!$C$2*MAX(E145,F145*Inputs!$C$3)) -> 402.4 | I145: =C145*(1+IF(A145>=Inputs!$D$5,Inputs!$D$4,0))*(1+Inputs!$D$2*MAX(E145,F145*Inputs!$D$3)) -> 402.4
A146: 45618 | B146: =TEXT(A146,"yyyy-mm") -> 2024-11 | C146: 402.4 | E146: 0 | F146: 0 | G146: =C146*(1+IF(A146>=Inputs!$B$5,Inputs!$B$4,0))*(1+Inputs!$B$2*MAX(E146,F146*Inputs!$B$3)) -> 402.4 | H146: =C146*(1+IF(A146>=Inputs!$C$5,Inputs!$C$4,0))*(1+Inputs!$C$2*MAX(E146,F146*Inputs!$C$3)) -> 402.4 | I146: =C146*(1+IF(A146>=Inputs!$D$5,Inputs!$D$4,0))*(1+Inputs!$D$2*MAX(E146,F146*Inputs!$D$3)) -> 402.4
...
